{"timestamp": 1755303467.4920013, "context": {"function_name": "test_recovery_function", "module_name": "__main__", "arguments": "{'args': (), 'kwargs': {}}", "timestamp": 1755303467.4920013, "severity": "medium", "category": "data_processing", "patient_id": null, "slide_id": null, "model_version": null, "retry_count": 0, "stack_trace": "Traceback (most recent call last):\n  File \"/root/repo/dgdm_histopath/utils/robust_error_handling.py\", line 172, in wrapper\n    result = func(*args, **kwargs)\n             ^^^^^^^^^^^^^^^^^^^^^\n  File \"/root/repo/test_generation2_robust.py\", line 154, in test_recovery_function\n    raise ValueError(\"Simulated error for testing\")\nValueError: Simulated error for testing\n"}, "exception": {"type": "ValueError", "message": "Simulated error for testing", "args": ["Simulated error for testing"]}}
{"timestamp": 1755303467.4920013, "context": {"function_name": "test_recovery_function", "module_name": "__main__", "arguments": "{'args': (), 'kwargs': {}}", "timestamp": 1755303467.4920013, "severity": "medium", "category": "data_processing", "patient_id": null, "slide_id": null, "model_version": null, "retry_count": 1, "stack_trace": "Traceback (most recent call last):\n  File \"/root/repo/dgdm_histopath/utils/robust_error_handling.py\", line 172, in wrapper\n    result = func(*args, **kwargs)\n             ^^^^^^^^^^^^^^^^^^^^^\n  File \"/root/repo/test_generation2_robust.py\", line 154, in test_recovery_function\n    raise ValueError(\"Simulated error for testing\")\nValueError: Simulated error for testing\n"}, "exception": {"type": "ValueError", "message": "Simulated error for testing", "args": ["Simulated error for testing"]}}
{"timestamp": 1755303467.4920013, "context": {"function_name": "test_recovery_function", "module_name": "__main__", "arguments": "{'args': (), 'kwargs': {}}", "timestamp": 1755303467.4920013, "severity": "medium", "category": "data_processing", "patient_id": null, "slide_id": null, "model_version": null, "retry_count": 2, "stack_trace": "Traceback (most recent call last):\n  File \"/root/repo/dgdm_histopath/utils/robust_error_handling.py\", line 172, in wrapper\n    result = func(*args, **kwargs)\n             ^^^^^^^^^^^^^^^^^^^^^\n  File \"/root/repo/test_generation2_robust.py\", line 154, in test_recovery_function\n    raise ValueError(\"Simulated error for testing\")\nValueError: Simulated error for testing\n"}, "exception": {"type": "ValueError", "message": "Simulated error for testing", "args": ["Simulated error for testing"]}}
{"timestamp": 1755303568.252563, "context": {"function_name": "test_recovery_function", "module_name": "__main__", "arguments": "{'args': (), 'kwargs': {}}", "timestamp": 1755303568.252563, "severity": "medium", "category": "data_processing", "patient_id": null, "slide_id": null, "model_version": null, "retry_count": 0, "stack_trace": "Traceback (most recent call last):\n  File \"/root/repo/dgdm_histopath/utils/robust_error_handling.py\", line 172, in wrapper\n    result = func(*args, **kwargs)\n             ^^^^^^^^^^^^^^^^^^^^^\n  File \"/root/repo/test_generation2_robust.py\", line 154, in test_recovery_function\n    raise ValueError(\"Simulated error for testing\")\nValueError: Simulated error for testing\n"}, "exception": {"type": "ValueError", "message": "Simulated error for testing", "args": ["Simulated error for testing"]}}
{"timestamp": 1755303568.252563, "context": {"function_name": "test_recovery_function", "module_name": "__main__", "arguments": "{'args': (), 'kwargs': {}}", "timestamp": 1755303568.252563, "severity": "medium", "category": "data_processing", "patient_id": null, "slide_id": null, "model_version": null, "retry_count": 1, "stack_trace": "Traceback (most recent call last):\n  File \"/root/repo/dgdm_histopath/utils/robust_error_handling.py\", line 172, in wrapper\n    result = func(*args, **kwargs)\n             ^^^^^^^^^^^^^^^^^^^^^\n  File \"/root/repo/test_generation2_robust.py\", line 154, in test_recovery_function\n    raise ValueError(\"Simulated error for testing\")\nValueError: Simulated error for testing\n"}, "exception": {"type": "ValueError", "message": "Simulated error for testing", "args": ["Simulated error for testing"]}}
{"timestamp": 1755303568.252563, "context": {"function_name": "test_recovery_function", "module_name": "__main__", "arguments": "{'args': (), 'kwargs': {}}", "timestamp": 1755303568.252563, "severity": "medium", "category": "data_processing", "patient_id": null, "slide_id": null, "model_version": null, "retry_count": 2, "stack_trace": "Traceback (most recent call last):\n  File \"/root/repo/dgdm_histopath/utils/robust_error_handling.py\", line 172, in wrapper\n    result = func(*args, **kwargs)\n             ^^^^^^^^^^^^^^^^^^^^^\n  File \"/root/repo/test_generation2_robust.py\", line 154, in test_recovery_function\n    raise ValueError(\"Simulated error for testing\")\nValueError: Simulated error for testing\n"}, "exception": {"type": "ValueError", "message": "Simulated error for testing", "args": ["Simulated error for testing"]}}
{"timestamp": 1755303622.931085, "context": {"function_name": "test_recovery_function", "module_name": "__main__", "arguments": "{'args': (), 'kwargs': {}}", "timestamp": 1755303622.931085, "severity": "medium", "category": "data_processing", "patient_id": null, "slide_id": null, "model_version": null, "retry_count": 0, "stack_trace": "Traceback (most recent call last):\n  File \"/root/repo/dgdm_histopath/utils/robust_error_handling.py\", line 172, in wrapper\n    result = func(*args, **kwargs)\n             ^^^^^^^^^^^^^^^^^^^^^\n  File \"/root/repo/test_generation2_robust.py\", line 154, in test_recovery_function\n    raise ValueError(\"Simulated error for testing\")\nValueError: Simulated error for testing\n"}, "exception": {"type": "ValueError", "message": "Simulated error for testing", "args": ["Simulated error for testing"]}}
{"timestamp": 1755303622.931085, "context": {"function_name": "test_recovery_function", "module_name": "__main__", "arguments": "{'args': (), 'kwargs': {}}", "timestamp": 1755303622.931085, "severity": "medium", "category": "data_processing", "patient_id": null, "slide_id": null, "model_version": null, "retry_count": 1, "stack_trace": "Traceback (most recent call last):\n  File \"/root/repo/dgdm_histopath/utils/robust_error_handling.py\", line 172, in wrapper\n    result = func(*args, **kwargs)\n             ^^^^^^^^^^^^^^^^^^^^^\n  File \"/root/repo/test_generation2_robust.py\", line 154, in test_recovery_function\n    raise ValueError(\"Simulated error for testing\")\nValueError: Simulated error for testing\n"}, "exception": {"type": "ValueError", "message": "Simulated error for testing", "args": ["Simulated error for testing"]}}
{"timestamp": 1755303622.931085, "context": {"function_name": "test_recovery_function", "module_name": "__main__", "arguments": "{'args': (), 'kwargs': {}}", "timestamp": 1755303622.931085, "severity": "medium", "category": "data_processing", "patient_id": null, "slide_id": null, "model_version": null, "retry_count": 2, "stack_trace": "Traceback (most recent call last):\n  File \"/root/repo/dgdm_histopath/utils/robust_error_handling.py\", line 172, in wrapper\n    result = func(*args, **kwargs)\n             ^^^^^^^^^^^^^^^^^^^^^\n  File \"/root/repo/test_generation2_robust.py\", line 154, in test_recovery_function\n    raise ValueError(\"Simulated error for testing\")\nValueError: Simulated error for testing\n"}, "exception": {"type": "ValueError", "message": "Simulated error for testing", "args": ["Simulated error for testing"]}}
{"timestamp": 1755304301.9207132, "context": {"function_name": "test_recovery_function", "module_name": "__main__", "arguments": "{'args': (), 'kwargs': {}}", "timestamp": 1755304301.9207132, "severity": "medium", "category": "data_processing", "patient_id": null, "slide_id": null, "model_version": null, "retry_count": 0, "stack_trace": "Traceback (most recent call last):\n  File \"/root/repo/dgdm_histopath/utils/robust_error_handling.py\", line 172, in wrapper\n    result = func(*args, **kwargs)\n             ^^^^^^^^^^^^^^^^^^^^^\n  File \"/root/repo/test_generation2_robust.py\", line 154, in test_recovery_function\n    raise ValueError(\"Simulated error for testing\")\nValueError: Simulated error for testing\n"}, "exception": {"type": "ValueError", "message": "Simulated error for testing", "args": ["Simulated error for testing"]}}
{"timestamp": 1755304301.9207132, "context": {"function_name": "test_recovery_function", "module_name": "__main__", "arguments": "{'args': (), 'kwargs': {}}", "timestamp": 1755304301.9207132, "severity": "medium", "category": "data_processing", "patient_id": null, "slide_id": null, "model_version": null, "retry_count": 1, "stack_trace": "Traceback (most recent call last):\n  File \"/root/repo/dgdm_histopath/utils/robust_error_handling.py\", line 172, in wrapper\n    result = func(*args, **kwargs)\n             ^^^^^^^^^^^^^^^^^^^^^\n  File \"/root/repo/test_generation2_robust.py\", line 154, in test_recovery_function\n    raise ValueError(\"Simulated error for testing\")\nValueError: Simulated error for testing\n"}, "exception": {"type": "ValueError", "message": "Simulated error for testing", "args": ["Simulated error for testing"]}}
{"timestamp": 1755304301.9207132, "context": {"function_name": "test_recovery_function", "module_name": "__main__", "arguments": "{'args': (), 'kwargs': {}}", "timestamp": 1755304301.9207132, "severity": "medium", "category": "data_processing", "patient_id": null, "slide_id": null, "model_version": null, "retry_count": 2, "stack_trace": "Traceback (most recent call last):\n  File \"/root/repo/dgdm_histopath/utils/robust_error_handling.py\", line 172, in wrapper\n    result = func(*args, **kwargs)\n             ^^^^^^^^^^^^^^^^^^^^^\n  File \"/root/repo/test_generation2_robust.py\", line 154, in test_recovery_function\n    raise ValueError(\"Simulated error for testing\")\nValueError: Simulated error for testing\n"}, "exception": {"type": "ValueError", "message": "Simulated error for testing", "args": ["Simulated error for testing"]}}
